Workbook

Sheet Guide
A1: Randori Geopolitical-Macro Risk Desk
A2: A spreadsheet build of the Randori Geopolitical Risk VaR methodology (draft of October 15, 2026) for 18 countries. It scores macro, political and event risk, turns the scores into probabilities and signals, maps each signal to trades, and runs a sample book through a Monte Carlo loss model.
A3: Status: the methodology is an untested draft and most inputs are seed estimates. No figure here should be quoted to a client or traded on before the data feeds are connected and the thresholds are fitted on the backtest.
A5: How the engine flows
A6: 1. Inputs and Country Profile | B6: 83 indicators across the seven pillars, plus market data, flags and tradable instruments for each country.
A7: 2. Stress Inputs | B7: Randori combined shock (depreciation, growth, rates, commodity or tourism export shock) applied to the eight stress-path indicators.
A8: 3. Base, Stress and Indicator Scores | B8: Each indicator scored 0-100 by straight-line interpolation between Rulebook thresholds; the worse of baseline and stress is kept.
A9: 4. Adjustments and Pillar Scores | B9: Weighted average blended with the worst indicator, plus trigger add-ons, capped analyst adjustments and override floors. Composite uses standard or small-state weights; grade = MIN(10, INT(score/10)+1).
A10: 5. Risk Engine | B10: Rule-based regime state (calm, stressed, crisis), 12-month default PD from rating prior + scorecard + market spread + text index in log-odds, and PDs for transfer and convertibility, expropriation, political violence and sanctions.
A11: 6. Signals | B11: 21 macro and event signals scored 0-100 per country.
A12: 7. Playbook and Trade Activation | B12: 22 strategies, each tied to a signal, a minimum strength, an optional second condition and the instrument it needs. A trade fires where all three hold; its conviction is the signal strength.
A13: 8. Portfolio VaR and MC | B13: Sample book through a Student-t copula with global and regional factors (loadings rise with the regime), 2,000 scenarios with a fixed seed. Expected loss, VaR 95/99, expected shortfall and each country's share of the tail.
A14: 9. Dashboard | B14: One row per country: score, grade, regime, PDs, top signals, the highest-conviction trade and a suggested size.
A16: Cell colors
A17: Blue text | B17: Inputs you can change (data, flags, weights, thresholds, book).
A18: Green fill | B18: IMF WEO October 2026 values pulled on October 19, 2026 (each carries a source note).
A19: Black text | B19: Formulas. Do not overwrite; change the inputs that feed them.
A21: Connecting the data feeds
A22: Where each indicator comes from | B22: Rulebook column P names the API or dataset for every indicator (IMF DataMapper codes, World Bank WDI/IDS codes, V-Dem, WGI, ACLED, UCDP and so on). Write pulls into the matching Inputs row; nothing else needs to change.
A23: Market data | B23: Country Profile rows P10-P13 (rating, spread, FX and reserve changes) should come from a market data feed; they drive the regime state and the market-implied PD.
A24: Scenario selector | B24: Assumptions B74: Model, All stressed or All crisis. It moves every country's regime, PD and LGD multipliers and copula loadings.
A26: Known limits of this version
A27: Regime state | B27: A threshold rule on spreads, FX and reserves stands in for the layer 3 hidden Markov model.
A28: Default PD | B28: Rating priors and the scorecard weight are starting values; layer 1 hazard model and layer 2 weights are not fitted yet.
A29: Monte Carlo | B29: 2,000 scenarios in-sheet (the methodology targets 100,000+ in code). The pseudo-random draws come from a deterministic hash of the seed, so results repeat exactly.
A30: Methodology fixes applied | B30: Worst-indicator blend 0.2 on indicators weighted 10%+ (fix 1), reserve stress only for pegs and dollarized economies (fix 2), both conditions for the boom trigger (fix 5), peg break kept out of the scorecard stress (fix 8). Change them on Assumptions.
A31: Advanced economies | B31: Thresholds are set for emerging and frontier sovereigns, so Japan and Singapore score high on debt ratios that their asset positions offset.
A32: Momentum | B32: The momentum signal stays at 0 until a prior composite is pasted into Country Profile row P27.
A33: Text stress index | B33: Placeholder zeros until the layer 2 language-model index is built.

Sheet Dashboard
A1: Geopolitical-Macro Risk Desk
A2: {="Highest composite risk: "&INDEX(A6:A23,MATCH(MAX(D6:D23),D6:D23,0))&" ("&TEXT(MAX(D6:D23),"0.0")&"). Lowest: "&INDEX(A6:A23,MATCH(MIN(D6:D23),D6:D23,0))&" ("&TEXT(MIN(D6:D23),"0.0")&"). Countries in the crisis regime: "&COUNTIF(F6:F23,"Crisis")&" of 18."} -> Highest composite risk: Venezuela (84.5). Lowest: Singapore (21.6). Countries in the crisis regime: 3 of 18.
A3: ="Sample book: $"&TEXT('Portfolio VaR'!E18,"#,##0")&"mm exposure, expected loss $"&TEXT('Portfolio VaR'!E20,"0.0")&"mm, 99% VaR $"&TEXT('Portfolio VaR'!E22,"0.0")&"mm, 99% expected shortfall $"&TEXT('Portfolio VaR'!E24,"0.0")&"mm. Scenario override: "&Assumptions!B74&"." -> Sample book: $305mm exposure, expected loss $12.2mm, 99% VaR $44.8mm, 99% expected shortfall $56.4mm. Scenario override: Model.
A5: Country | B5: Column (helper) | C5: Region | D5: Composite score | E5: Grade | F5: Regime | G5: Rating | H5: Default PD (12m) | I5: Market-implied PD | J5: Any loss event PD | K5: Top three risk signals | L5: Trades firing | M5: Highest-conviction trade | N5: Conviction | O5: Suggested notional ($mm) | P5: All trades firing
A6: Vietnam | B6: =MATCH(A6,'Risk Engine'!$E$4:$V$4,0) -> 1 | C6: {=INDEX('Country Profile'!$E$6:$V$6,$B6)} -> Asia | D6: {=INDEX('Risk Engine'!$E$5:$V$5,$B6)} -> 29.120279 | E6: {=INDEX('Risk Engine'!$E$6:$V$6,$B6)} -> 3 | F6: {=INDEX('Risk Engine'!$E$8:$V$8,$B6)} -> Calm | G6: {=INDEX('Risk Engine'!$E$11:$V$11,$B6)} -> BB+ | H6: {=INDEX('Risk Engine'!$E$19:$V$19,$B6)} -> 0.0043255458 | I6: {=INDEX('Risk Engine'!$E$14:$V$14,$B6)} -> 0.016666667 | J6: {=INDEX('Risk Engine'!$E$29:$V$29,$B6)} -> 0.036404391 | K6: =IFERROR(__xludf.DUMMYFUNCTION("IFERROR(TEXTJOIN("", "",TRUE,SORTN(FILTER(Signals!$B$5:$B$22,INDEX(Signals!$E$5:$V$22,0,$B6)>=Assumptions!$B$65),3,0,FILTER(INDEX(Signals!$E$5:$V$22,0,$B6),INDEX(Signals!$E$5:$V$22,0,$B6)>=Assumptions!$B$65),FALSE)),""None above threshold"")"),"None above threshold") -> None above threshold | L6: {=COUNT(INDEX('Trade Activation'!$E$5:$V$26,0,$B6))} -> 1 | M6: {=IF(L6=0,"None",INDEX(Playbook!$B$5:$B$26,MATCH(MAX(INDEX('Trade Activation'!$E$5:$V$26,0,$B6)),INDEX('Trade Activation'!$E$5:$V$26,0,$B6),0)))} -> Overweight equities in low-risk calm markets | N6: {=MAX(INDEX('Trade Activation'!$E$5:$V$26,0,$B6))} -> 71 | O6: {=Assumptions!$B$68*N6/100*INDEX(Assumptions!$E$52:$E$54,MATCH(F6,Assumptions!$A$52:$A$54,0))} -> 7.1 | P6: =IFERROR(__xludf.DUMMYFUNCTION("IF(L6=0,"""",TEXTJOIN("", "",TRUE,FILTER(Playbook!$A$5:$A$26,INDEX('Trade Activation'!$E$5:$V$26,0,$B6)<>"""")))"),"T20") -> T20
A7: Philippines | B7: =MATCH(A7,'Risk Engine'!$E$4:$V$4,0) -> 2 | C7: {=INDEX('Country Profile'!$E$6:$V$6,$B7)} -> Asia | D7: {=INDEX('Risk Engine'!$E$5:$V$5,$B7)} -> 36.499095 | E7: {=INDEX('Risk Engine'!$E$6:$V$6,$B7)} -> 4 | F7: {=INDEX('Risk Engine'!$E$8:$V$8,$B7)} -> Calm | G7: {=INDEX('Risk Engine'!$E$11:$V$11,$B7)} -> BBB+ | H7: {=INDEX('Risk Engine'!$E$19:$V$19,$B7)} -> 0.002599347 | I7: {=INDEX('Risk Engine'!$E$14:$V$14,$B7)} -> 0.010833333 | J7: {=INDEX('Risk Engine'!$E$29:$V$29,$B7)} -> 0.02833332 | K7: =IFERROR(__xludf.DUMMYFUNCTION("IFERROR(TEXTJOIN("", "",TRUE,SORTN(FILTER(Signals!$B$5:$B$22,INDEX(Signals!$E$5:$V$22,0,$B7)>=Assumptions!$B$65),3,0,FILTER(INDEX(Signals!$E$5:$V$22,0,$B7),INDEX(Signals!$E$5:$V$22,0,$B7)>=Assumptions!$B$65),FALSE)),""None above threshold"")"),"Debt payment wall") -> Debt payment wall | L7: {=COUNT(INDEX('Trade Activation'!$E$5:$V$26,0,$B7))} -> 1 | M7: {=IF(L7=0,"None",INDEX(Playbook!$B$5:$B$26,MATCH(MAX(INDEX('Trade Activation'!$E$5:$V$26,0,$B7)),INDEX('Trade Activation'!$E$5:$V$26,0,$B7),0)))} -> FX carry in calm regimes | N7: {=MAX(INDEX('Trade Activation'!$E$5:$V$26,0,$B7))} -> 64 | O7: {=Assumptions!$B$68*N7/100*INDEX(Assumptions!$E$52:$E$54,MATCH(F7,Assumptions!$A$52:$A$54,0))} -> 6.4 | P7: =IFERROR(__xludf.DUMMYFUNCTION("IF(L7=0,"""",TEXTJOIN("", "",TRUE,FILTER(Playbook!$A$5:$A$26,INDEX('Trade Activation'!$E$5:$V$26,0,$B7)<>"""")))"),"T19") -> T19
A8: China | B8: =MATCH(A8,'Risk Engine'!$E$4:$V$4,0) -> 3 | C8: {=INDEX('Country Profile'!$E$6:$V$6,$B8)} -> Asia | D8: {=INDEX('Risk Engine'!$E$5:$V$5,$B8)} -> 40.318022 | E8: {=INDEX('Risk Engine'!$E$6:$V$6,$B8)} -> 5 | F8: {=INDEX('Risk Engine'!$E$8:$V$8,$B8)} -> Calm | G8: {=INDEX('Risk Engine'!$E$11:$V$11,$B8)} -> A+ | H8: {=INDEX('Risk Engine'!$E$19:$V$19,$B8)} -> 0.0018043773 | I8: {=INDEX('Risk Engine'!$E$14:$V$14,$B8)} -> 0.01 | J8: {=INDEX('Risk Engine'!$E$29:$V$29,$B8)} -> 0.037334729 | K8: =IFERROR(__xludf.DUMMYFUNCTION("IFERROR(TEXTJOIN("", "",TRUE,SORTN(FILTER(Signals!$B$5:$B$22,INDEX(Signals!$E$5:$V$22,0,$B8)>=Assumptions!$B$65),3,0,FILTER(INDEX(Signals!$E$5:$V$22,0,$B8),INDEX(Signals!$E$5:$V$22,0,$B8)>=Assumptions!$B$65),FALSE)),""None above threshold"")"),"Sanctions and geopolitics") -> Sanctions and geopolitics | L8: {=COUNT(INDEX('Trade Activation'!$E$5:$V$26,0,$B8))} -> 2 | M8: {=IF(L8=0,"None",INDEX(Playbook!$B$5:$B$26,MATCH(MAX(INDEX('Trade Activation'!$E$5:$V$26,0,$B8)),INDEX('Trade Activation'!$E$5:$V$26,0,$B8),0)))} -> Sanctions and tariff screen with safe-haven hedge | N8: {=MAX(INDEX('Trade Activation'!$E$5:$V$26,0,$B8))} -> 75 | O8: {=Assumptions!$B$68*N8/100*INDEX(Assumptions!$E$52:$E$54,MATCH(F8,Assumptions!$A$52:$A$54,0))} -> 7.5 | P8: =IFERROR(__xludf.DUMMYFUNCTION("IF(L8=0,"""",TEXTJOIN("", "",TRUE,FILTER(Playbook!$A$5:$A$26,INDEX('Trade Activation'!$E$5:$V$26,0,$B8)<>"""")))"),"T07, T15") -> T07, T15
A9: Malaysia | B9: =MATCH(A9,'Risk Engine'!$E$4:$V$4,0) -> 4 | C9: {=INDEX('Country Profile'!$E$6:$V$6,$B9)} -> Asia | D9: {=INDEX('Risk Engine'!$E$5:$V$5,$B9)} -> 30.992372 | E9: {=INDEX('Risk Engine'!$E$6:$V$6,$B9)} -> 4 | F9: {=INDEX('Risk Engine'!$E$8:$V$8,$B9)} -> Calm | G9: {=INDEX('Risk Engine'!$E$11:$V$11,$B9)} -> A- | H9: {=INDEX('Risk Engine'!$E$19:$V$19,$B9)} -> 0.0014427387 | I9: {=INDEX('Risk Engine'!$E$14:$V$14,$B9)} -> 0.0075 | J9: {=INDEX('Risk Engine'!$E$29:$V$29,$B9)} -> 0.020036742 | K9: =IFERROR(__xludf.DUMMYFUNCTION("IFERROR(TEXTJOIN("", "",TRUE,SORTN(FILTER(Signals!$B$5:$B$22,INDEX(Signals!$E$5:$V$22,0,$B9)>=Assumptions!$B$65),3,0,FILTER(INDEX(Signals!$E$5:$V$22,0,$B9),INDEX(Signals!$E$5:$V$22,0,$B9)>=Assumptions!$B$65),FALSE)),""None above threshold"")"),"None above threshold") -> None above threshold | L9: {=COUNT(INDEX('Trade Activation'!$E$5:$V$26,0,$B9))} -> 1 | M9: {=IF(L9=0,"None",INDEX(Playbook!$B$5:$B$26,MATCH(MAX(INDEX('Trade Activation'!$E$5:$V$26,0,$B9)),INDEX('Trade Activation'!$E$5:$V$26,0,$B9),0)))} -> Overweight equities in low-risk calm markets | N9: {=MAX(INDEX('Trade Activation'!$E$5:$V$26,0,$B9))} -> 69 | O9: {=Assumptions!$B$68*N9/100*INDEX(Assumptions!$E$52:$E$54,MATCH(F9,Assumptions!$A$52:$A$54,0))} -> 6.9 | P9: =IFERROR(__xludf.DUMMYFUNCTION("IF(L9=0,"""",TEXTJOIN("", "",TRUE,FILTER(Playbook!$A$5:$A$26,INDEX('Trade Activation'!$E$5:$V$26,0,$B9)<>"""")))"),"T20") -> T20
A10: Singapore | B10: =MATCH(A10,'Risk Engine'!$E$4:$V$4,0) -> 5 | C10: {=INDEX('Country Profile'!$E$6:$V$6,$B10)} -> Asia | D10: {=INDEX('Risk Engine'!$E$5:$V$5,$B10)} -> 21.569474 | E10: {=INDEX('Risk Engine'!$E$6:$V$6,$B10)} -> 3 | F10: {=INDEX('Risk Engine'!$E$8:$V$8,$B10)} -> Calm | G10: {=INDEX('Risk Engine'!$E$11:$V$11,$B10)} -> AAA | H10: {=INDEX('Risk Engine'!$E$19:$V$19,$B10)} -> 0.00019014843 | I10: {=INDEX('Risk Engine'!$E$14:$V$14,$B10)} -> 0.0025 | J10: {=INDEX('Risk Engine'!$E$29:$V$29,$B10)} -> 0.010216231 | K10: =IFERROR(__xludf.DUMMYFUNCTION("IFERROR(TEXTJOIN("", "",TRUE,SORTN(FILTER(Signals!$B$5:$B$22,INDEX(Signals!$E$5:$V$22,0,$B10)>=Assumptions!$B$65),3,0,FILTER(INDEX(Signals!$E$5:$V$22,0,$B10),INDEX(Signals!$E$5:$V$22,0,$B10)>=Assumptions!$B$65),FALSE)),""None above threshold"")"),"Growth slowdown") -> Growth slowdown | L10: {=COUNT(INDEX('Trade Activation'!$E$5:$V$26,0,$B10))} -> 2 | M10: {=IF(L10=0,"None",INDEX(Playbook!$B$5:$B$26,MATCH(MAX(INDEX('Trade Activation'!$E$5:$V$26,0,$B10)),INDEX('Trade Activation'!$E$5:$V$26,0,$B10),0)))} -> Overweight equities in low-risk calm markets | N10: {=MAX(INDEX('Trade Activation'!$E$5:$V$26,0,$B10))} -> 78 | O10: {=Assumptions!$B$68*N10/100*INDEX(Assumptions!$E$52:$E$54,MATCH(F10,Assumptions!$A$52:$A$54,0))} -> 7.8 | P10: =IFERROR(__xludf.DUMMYFUNCTION("IF(L10=0,"""",TEXTJOIN("", "",TRUE,FILTER(Playbook!$A$5:$A$26,INDEX('Trade Activation'!$E$5:$V$26,0,$B10)<>"""")))"),"T07, T20") -> T07, T20
A11: Japan | B11: =MATCH(A11,'Risk Engine'!$E$4:$V$4,0) -> 6 | C11: {=INDEX('Country Profile'!$E$6:$V$6,$B11)} -> Asia | D11: {=INDEX('Risk Engine'!$E$5:$V$5,$B11)} -> 23.857281 | E11: {=INDEX('Risk Engine'!$E$6:$V$6,$B11)} -> 3 | F11: {=INDEX('Risk Engine'!$E$8:$V$8,$B11)} -> Calm | G11: {=INDEX('Risk Engine'!$E$11:$V$11,$B11)} -> A+ | H11: {=INDEX('Risk Engine'!$E$19:$V$19,$B11)} -> 0.00053815523 | I11: {=INDEX('Risk Engine'!$E$14:$V$14,$B11)} -> 0.0033333333 | J11: {=INDEX('Risk Engine'!$E$29:$V$29,$B11)} -> 0.0096306509 | K11: =IFERROR(__xludf.DUMMYFUNCTION("IFERROR(TEXTJOIN("", "",TRUE,SORTN(FILTER(Signals!$B$5:$B$22,INDEX(Signals!$E$5:$V$22,0,$B11)>=Assumptions!$B$65),3,0,FILTER(INDEX(Signals!$E$5:$V$22,0,$B11),INDEX(Signals!$E$5:$V$22,0,$B11)>=Assumptions!$B$65),FALSE)),""None above threshold"")"),"Growth slowdown") -> Growth slowdown | L11: {=COUNT(INDEX('Trade Activation'!$E$5:$V$26,0,$B11))} -> 2 | M11: {=IF(L11=0,"None",INDEX(Playbook!$B$5:$B$26,MATCH(MAX(INDEX('Trade Activation'!$E$5:$V$26,0,$B11)),INDEX('Trade Activation'!$E$5:$V$26,0,$B11),0)))} -> Receive local duration on a growth slowdown | N11: {=MAX(INDEX('Trade Activation'!$E$5:$V$26,0,$B11))} -> 93 | O11: {=Assumptions!$B$68*N11/100*INDEX(Assumptions!$E$52:$E$54,MATCH(F11,Assumptions!$A$52:$A$54,0))} -> 9.3 | P11: =IFERROR(__xludf.DUMMYFUNCTION("IF(L11=0,"""",TEXTJOIN("", "",TRUE,FILTER(Playbook!$A$5:$A$26,INDEX('Trade Activation'!$E$5:$V$26,0,$B11)<>"""")))"),"T07, T20") -> T07, T20
A12: South Korea | B12: =MATCH(A12,'Risk Engine'!$E$4:$V$4,0) -> 7 | C12: {=INDEX('Country Profile'!$E$6:$V$6,$B12)} -> Asia | D12: {=INDEX('Risk Engine'!$E$5:$V$5,$B12)} -> 21.968328 | E12: {=INDEX('Risk Engine'!$E$6:$V$6,$B12)} -> 3 | F12: {=INDEX('Risk Engine'!$E$8:$V$8,$B12)} -> Calm | G12: {=INDEX('Risk Engine'!$E$11:$V$11,$B12)} -> AA | H12: {=INDEX('Risk Engine'!$E$19:$V$19,$B12)} -> 0.00043232257 | I12: {=INDEX('Risk Engine'!$E$14:$V$14,$B12)} -> 0.0041666667 | J12: {=INDEX('Risk Engine'!$E$29:$V$29,$B12)} -> 0.014902246 | K12: =IFERROR(__xludf.DUMMYFUNCTION("IFERROR(TEXTJOIN("", "",TRUE,SORTN(FILTER(Signals!$B$5:$B$22,INDEX(Signals!$E$5:$V$22,0,$B12)>=Assumptions!$B$65),3,0,FILTER(INDEX(Signals!$E$5:$V$22,0,$B12),INDEX(Signals!$E$5:$V$22,0,$B12)>=Assumptions!$B$65),FALSE)),""None above threshold"")"),"Growth slowdown") -> Growth slowdown | L12: {=COUNT(INDEX('Trade Activation'!$E$5:$V$26,0,$B12))} -> 2 | M12: {=IF(L12=0,"None",INDEX(Playbook!$B$5:$B$26,MATCH(MAX(INDEX('Trade Activation'!$E$5:$V$26,0,$B12)),INDEX('Trade Activation'!$E$5:$V$26,0,$B12),0)))} -> Overweight equities in low-risk calm markets | N12: {=MAX(INDEX('Trade Activation'!$E$5:$V$26,0,$B12))} -> 78 | O12: {=Assumptions!$B$68*N12/100*INDEX(Assumptions!$E$52:$E$54,MATCH(F12,Assumptions!$A$52:$A$54,0))} -> 7.8 | P12: =IFERROR(__xludf.DUMMYFUNCTION("IF(L12=0,"""",TEXTJOIN("", "",TRUE,FILTER(Playbook!$A$5:$A$26,INDEX('Trade Activation'!$E$5:$V$26,0,$B12)<>"""")))"),"T07, T20") -> T07, T20
A13: India | B13: =MATCH(A13,'Risk Engine'!$E$4:$V$4,0) -> 8 | C13: {=INDEX('Country Profile'!$E$6:$V$6,$B13)} -> Asia | D13: {=INDEX('Risk Engine'!$E$5:$V$5,$B13)} -> 36.361175 | E13: {=INDEX('Risk Engine'!$E$6:$V$6,$B13)} -> 4 | F13: {=INDEX('Risk Engine'!$E$8:$V$8,$B13)} -> Calm | G13: {=INDEX('Risk Engine'!$E$11:$V$11,$B13)} -> BBB | H13: {=INDEX('Risk Engine'!$E$19:$V$19,$B13)} -> 0.0032433872 | I13: {=INDEX('Risk Engine'!$E$14:$V$14,$B13)} -> 0.011666667 | J13: {=INDEX('Risk Engine'!$E$29:$V$29,$B13)} -> 0.030951389 | K13: =IFERROR(__xludf.DUMMYFUNCTION("IFERROR(TEXTJOIN("", "",TRUE,SORTN(FILTER(Signals!$B$5:$B$22,INDEX(Signals!$E$5:$V$22,0,$B13)>=Assumptions!$B$65),3,0,FILTER(INDEX(Signals!$E$5:$V$22,0,$B13),INDEX(Signals!$E$5:$V$22,0,$B13)>=Assumptions!$B$65),FALSE)),""None above threshold"")"),"Debt payment wall, Sanctions and geopolitics") -> Debt payment wall, Sanctions and geopolitics | L13: {=COUNT(INDEX('Trade Activation'!$E$5:$V$26,0,$B13))} -> 3 | M13: {=IF(L13=0,"None",INDEX(Playbook!$B$5:$B$26,MATCH(MAX(INDEX('Trade Activation'!$E$5:$V$26,0,$B13)),INDEX('Trade Activation'!$E$5:$V$26,0,$B13),0)))} -> Sanctions and tariff screen with safe-haven hedge | N13: {=MAX(INDEX('Trade Activation'!$E$5:$V$26,0,$B13))} -> 75 | O13: {=Assumptions!$B$68*N13/100*INDEX(Assumptions!$E$52:$E$54,MATCH(F13,Assumptions!$A$52:$A$54,0))} -> 7.5 | P13: =IFERROR(__xludf.DUMMYFUNCTION("IF(L13=0,"""",TEXTJOIN("", "",TRUE,FILTER(Playbook!$A$5:$A$26,INDEX('Trade Activation'!$E$5:$V$26,0,$B13)<>"""")))"),"T15, T19, T20") -> T15, T19, T20
A14: Pakistan | B14: =MATCH(A14,'Risk Engine'!$E$4:$V$4,0) -> 9 | C14: {=INDEX('Country Profile'!$E$6:$V$6,$B14)} -> Asia | D14: {=INDEX('Risk Engine'!$E$5:$V$5,$B14)} -> 66.910129 | E14: {=INDEX('Risk Engine'!$E$6:$V$6,$B14)} -> 7 | F14: {=INDEX('Risk Engine'!$E$8:$V$8,$B14)} -> Stressed | G14: {=INDEX('Risk Engine'!$E$11:$V$11,$B14)} -> B- | H14: {=INDEX('Risk Engine'!$E$19:$V$19,$B14)} -> 0.16510446 | I14: {=INDEX('Risk Engine'!$E$14:$V$14,$B14)} -> 0.075 | J14: {=INDEX('Risk Engine'!$E$29:$V$29,$B14)} -> 0.29463078 | K14: =IFERROR(__xludf.DUMMYFUNCTION("IFERROR(TEXTJOIN("", "",TRUE,SORTN(FILTER(Signals!$B$5:$B$22,INDEX(Signals!$E$5:$V$22,0,$B14)>=Assumptions!$B$65),3,0,FILTER(INDEX(Signals!$E$5:$V$22,0,$B14),INDEX(Signals!$E$5:$V$22,0,$B14)>=Assumptions!$B$65),FALSE)),""None above threshold"")"),"Debt payment wall, Market complacency, Security and violence") -> Debt payment wall, Market complacency, Security and violence | L14: {=COUNT(INDEX('Trade Activation'!$E$5:$V$26,0,$B14))} -> 9 | M14: {=IF(L14=0,"None",INDEX(Playbook!$B$5:$B$26,MATCH(MAX(INDEX('Trade Activation'!$E$5:$V$26,0,$B14)),INDEX('Trade Activation'!$E$5:$V$26,0,$B14),0)))} -> CDS curve flattener into a payment wall | N14: {=MAX(INDEX('Trade Activation'!$E$5:$V$26,0,$B14))} -> 100 | O14: {=Assumptions!$B$68*N14/100*INDEX(Assumptions!$E$52:$E$54,MATCH(F14,Assumptions!$A$52:$A$54,0))} -> 7.5 | P14: =IFERROR(__xludf.DUMMYFUNCTION("IF(L14=0,"""",TEXTJOIN("", "",TRUE,FILTER(Playbook!$A$5:$A$26,INDEX('Trade Activation'!$E$5:$V$26,0,$B14)<>"""")))"),"T01, T02, T03, T11, T12, T14, T15, T16, T22") -> T01, T02, T03, T11, T12, T14, T15, T16, T22
A15: Belize | B15: =MATCH(A15,'Risk Engine'!$E$4:$V$4,0) -> 10 | C15: {=INDEX('Country Profile'!$E$6:$V$6,$B15)} -> LatAm | D15: {=INDEX('Risk Engine'!$E$5:$V$5,$B15)} -> 48.850579 | E15: {=INDEX('Risk Engine'!$E$6:$V$6,$B15)} -> 5 | F15: {=INDEX('Risk Engine'!$E$8:$V$8,$B15)} -> Stressed | G15: {=INDEX('Risk Engine'!$E$11:$V$11,$B15)} -> B- | H15: {=INDEX('Risk Engine'!$E$19:$V$19,$B15)} -> 0.10369648 | I15: {=INDEX('Risk Engine'!$E$14:$V$14,$B15)} -> 0.10833333 | J15: {=INDEX('Risk Engine'!$E$29:$V$29,$B15)} -> 0.16635742 | K15: =IFERROR(__xludf.DUMMYFUNCTION("IFERROR(TEXTJOIN("", "",TRUE,SORTN(FILTER(Signals!$B$5:$B$22,INDEX(Signals!$E$5:$V$22,0,$B15)>=Assumptions!$B$65),3,0,FILTER(INDEX(Signals!$E$5:$V$22,0,$B15),INDEX(Signals!$E$5:$V$22,0,$B15)>=Assumptions!$B$65),FALSE)),""None above threshold"")"),"Growth slowdown, Climate and disaster, Expropriation and contract risk") -> Growth slowdown, Climate and disaster, Expropriation and contract risk | L15: {=COUNT(INDEX('Trade Activation'!$E$5:$V$26,0,$B15))} -> 2 | M15: {=IF(L15=0,"None",INDEX(Playbook!$B$5:$B$26,MATCH(MAX(INDEX('Trade Activation'!$E$5:$V$26,0,$B15)),INDEX('Trade Activation'!$E$5:$V$26,0,$B15),0)))} -> Pre-season climate and disaster hedge | N15: {=MAX(INDEX('Trade Activation'!$E$5:$V$26,0,$B15))} -> 70 | O15: {=Assumptions!$B$68*N15/100*INDEX(Assumptions!$E$52:$E$54,MATCH(F15,Assumptions!$A$52:$A$54,0))} -> 5.25 | P15: =IFERROR(__xludf.DUMMYFUNCTION("IF(L15=0,"""",TEXTJOIN("", "",TRUE,FILTER(Playbook!$A$5:$A$26,INDEX('Trade Activation'!$E$5:$V$26,0,$B15)<>"""")))"),"T11, T14") -> T11, T14
A16: Brazil | B16: =MATCH(A16,'Risk Engine'!$E$4:$V$4,0) -> 11 | C16: {=INDEX('Country Profile'!$E$6:$V$6,$B16)} -> LatAm | D16: {=INDEX('Risk Engine'!$E$5:$V$5,$B16)} -> 42.978174 | E16: {=INDEX('Risk Engine'!$E$6:$V$6,$B16)} -> 5 | F16: {=INDEX('Risk Engine'!$E$8:$V$8,$B16)} -> Calm | G16: {=INDEX('Risk Engine'!$E$11:$V$11,$B16)} -> BB | H16: {=INDEX('Risk Engine'!$E$19:$V$19,$B16)} -> 0.011833244 | I16: {=INDEX('Risk Engine'!$E$14:$V$14,$B16)} -> 0.026666667 | J16: {=INDEX('Risk Engine'!$E$29:$V$29,$B16)} -> 0.046446681 | K16: =IFERROR(__xludf.DUMMYFUNCTION("IFERROR(TEXTJOIN("", "",TRUE,SORTN(FILTER(Signals!$B$5:$B$22,INDEX(Signals!$E$5:$V$22,0,$B16)>=Assumptions!$B$65),3,0,FILTER(INDEX(Signals!$E$5:$V$22,0,$B16),INDEX(Signals!$E$5:$V$22,0,$B16)>=Assumptions!$B$65),FALSE)),""None above threshold"")"),"Growth slowdown, Sanctions and geopolitics, Debt payment wall") -> Growth slowdown, Sanctions and geopolitics, Debt payment wall | L16: {=COUNT(INDEX('Trade Activation'!$E$5:$V$26,0,$B16))} -> 5 | M16: {=IF(L16=0,"None",INDEX(Playbook!$B$5:$B$26,MATCH(MAX(INDEX('Trade Activation'!$E$5:$V$26,0,$B16)),INDEX('Trade Activation'!$E$5:$V$26,0,$B16),0)))} -> Sell protection or buy bonds where spreads overprice risk | N16: {=MAX(INDEX('Trade Activation'!$E$5:$V$26,0,$B16))} -> 100 | O16: {=Assumptions!$B$68*N16/100*INDEX(Assumptions!$E$52:$E$54,MATCH(F16,Assumptions!$A$52:$A$54,0))} -> 10 | P16: =IFERROR(__xludf.DUMMYFUNCTION("IF(L16=0,"""",TEXTJOIN("", "",TRUE,FILTER(Playbook!$A$5:$A$26,INDEX('Trade Activation'!$E$5:$V$26,0,$B16)<>"""")))"),"T06, T09, T15, T17, T19") -> T06, T09, T15, T17, T19
A17: Argentina | B17: =MATCH(A17,'Risk Engine'!$E$4:$V$4,0) -> 12 | C17: {=INDEX('Country Profile'!$E$6:$V$6,$B17)} -> LatAm | D17: {=INDEX('Risk Engine'!$E$5:$V$5,$B17)} -> 56.432417 | E17: {=INDEX('Risk Engine'!$E$6:$V$6,$B17)} -> 6 | F17: {=INDEX('Risk Engine'!$E$8:$V$8,$B17)} -> Stressed | G17: {=INDEX('Risk Engine'!$E$11:$V$11,$B17)} -> B- | H17: {=INDEX('Risk Engine'!$E$19:$V$19,$B17)} -> 0.13642498 | I17: {=INDEX('Risk Engine'!$E$14:$V$14,$B17)} -> 0.10833333 | J17: {=INDEX('Risk Engine'!$E$29:$V$29,$B17)} -> 0.23185988 | K17: =IFERROR(__xludf.DUMMYFUNCTION("IFERROR(TEXTJOIN("", "",TRUE,SORTN(FILTER(Signals!$B$5:$B$22,INDEX(Signals!$E$5:$V$22,0,$B17)>=Assumptions!$B$65),3,0,FILTER(INDEX(Signals!$E$5:$V$22,0,$B17),INDEX(Signals!$E$5:$V$22,0,$B17)>=Assumptions!$B$65),FALSE)),""None above threshold"")"),"Inflation pressure, Debt payment wall, Devaluation pressure") -> Inflation pressure, Debt payment wall, Devaluation pressure | L17: {=COUNT(INDEX('Trade Activation'!$E$5:$V$26,0,$B17))} -> 6 | M17: {=IF(L17=0,"None",INDEX(Playbook!$B$5:$B$26,MATCH(MAX(INDEX('Trade Activation'!$E$5:$V$26,0,$B17)),INDEX('Trade Activation'!$E$5:$V$26,0,$B17),0)))} -> Pay short-dated local rates | N17: {=MAX(INDEX('Trade Activation'!$E$5:$V$26,0,$B17))} -> 96 | O17: {=Assumptions!$B$68*N17/100*INDEX(Assumptions!$E$52:$E$54,MATCH(F17,Assumptions!$A$52:$A$54,0))} -> 7.2 | P17: =IFERROR(__xludf.DUMMYFUNCTION("IF(L17=0,"""",TEXTJOIN("", "",TRUE,FILTER(Playbook!$A$5:$A$26,INDEX('Trade Activation'!$E$5:$V$26,0,$B17)<>"""")))"),"T01, T02, T03, T04, T06, T22") -> T01, T02, T03, T04, T06, T22
A18: Colombia | B18: =MATCH(A18,'Risk Engine'!$E$4:$V$4,0) -> 13 | C18: {=INDEX('Country Profile'!$E$6:$V$6,$B18)} -> LatAm | D18: {=INDEX('Risk Engine'!$E$5:$V$5,$B18)} -> 40.737128 | E18: {=INDEX('Risk Engine'!$E$6:$V$6,$B18)} -> 5 | F18: {=INDEX('Risk Engine'!$E$8:$V$8,$B18)} -> Calm | G18: {=INDEX('Risk Engine'!$E$11:$V$11,$B18)} -> BB | H18: {=INDEX('Risk Engine'!$E$19:$V$19,$B18)} -> 0.012739959 | I18: {=INDEX('Risk Engine'!$E$14:$V$14,$B18)} -> 0.036666667 | J18: {=INDEX('Risk Engine'!$E$29:$V$29,$B18)} -> 0.050629163 | K18: =IFERROR(__xludf.DUMMYFUNCTION("IFERROR(TEXTJOIN("", "",TRUE,SORTN(FILTER(Signals!$B$5:$B$22,INDEX(Signals!$E$5:$V$22,0,$B18)>=Assumptions!$B$65),3,0,FILTER(INDEX(Signals!$E$5:$V$22,0,$B18),INDEX(Signals!$E$5:$V$22,0,$B18)>=Assumptions!$B$65),FALSE)),""None above threshold"")"),"Growth slowdown, Security and violence") -> Growth slowdown, Security and violence | L18: {=COUNT(INDEX('Trade Activation'!$E$5:$V$26,0,$B18))} -> 4 | M18: {=IF(L18=0,"None",INDEX(Playbook!$B$5:$B$26,MATCH(MAX(INDEX('Trade Activation'!$E$5:$V$26,0,$B18)),INDEX('Trade Activation'!$E$5:$V$26,0,$B18),0)))} -> Sell protection or buy bonds where spreads overprice risk | N18: {=MAX(INDEX('Trade Activation'!$E$5:$V$26,0,$B18))} -> 100 | O18: {=Assumptions!$B$68*N18/100*INDEX(Assumptions!$E$52:$E$54,MATCH(F18,Assumptions!$A$52:$A$54,0))} -> 10 | P18: =IFERROR(__xludf.DUMMYFUNCTION("IF(L18=0,"""",TEXTJOIN("", "",TRUE,FILTER(Playbook!$A$5:$A$26,INDEX('Trade Activation'!$E$5:$V$26,0,$B18)<>"""")))"),"T06, T12, T17, T19") -> T06, T12, T17, T19
A19: Venezuela | B19: =MATCH(A19,'Risk Engine'!$E$4:$V$4,0) -> 14 | C19: {=INDEX('Country Profile'!$E$6:$V$6,$B19)} -> LatAm | D19: {=INDEX('Risk Engine'!$E$5:$V$5,$B19)} -> 84.483114 | E19: {=INDEX('Risk Engine'!$E$6:$V$6,$B19)} -> 9 | F19: {=INDEX('Risk Engine'!$E$8:$V$8,$B19)} -> Crisis | G19: {=INDEX('Risk Engine'!$E$11:$V$11,$B19)} -> SD | H19: {=INDEX('Risk Engine'!$E$19:$V$19,$B19)} -> 0.99 | I19: {=INDEX('Risk Engine'!$E$14:$V$14,$B19)} -> 0.95 | J19: {=INDEX('Risk Engine'!$E$29:$V$29,$B19)} -> 0.99471269 | K19: =IFERROR(__xludf.DUMMYFUNCTION("IFERROR(TEXTJOIN("", "",TRUE,SORTN(FILTER(Signals!$B$5:$B$22,INDEX(Signals!$E$5:$V$22,0,$B19)>=Assumptions!$B$65),3,0,FILTER(INDEX(Signals!$E$5:$V$22,0,$B19),INDEX(Signals!$E$5:$V$22,0,$B19)>=Assumptions!$B$65),FALSE)),""None above threshold"")"),"Debt payment wall, Devaluation pressure, Inflation pressure") -> Debt payment wall, Devaluation pressure, Inflation pressure | L19: {=COUNT(INDEX('Trade Activation'!$E$5:$V$26,0,$B19))} -> 6 | M19: {=IF(L19=0,"None",INDEX(Playbook!$B$5:$B$26,MATCH(MAX(INDEX('Trade Activation'!$E$5:$V$26,0,$B19)),INDEX('Trade Activation'!$E$5:$V$26,0,$B19),0)))} -> Commodity-linked downside hedge | N19: {=MAX(INDEX('Trade Activation'!$E$5:$V$26,0,$B19))} -> 100 | O19: {=Assumptions!$B$68*N19/100*INDEX(Assumptions!$E$52:$E$54,MATCH(F19,Assumptions!$A$52:$A$54,0))} -> 5 | P19: =IFERROR(__xludf.DUMMYFUNCTION("IF(L19=0,"""",TEXTJOIN("", "",TRUE,FILTER(Playbook!$A$5:$A$26,INDEX('Trade Activation'!$E$5:$V$26,0,$B19)<>"""")))"),"T03, T11, T13, T15, T18, T22") -> T03, T11, T13, T15, T18, T22
A20: Nigeria | B20: =MATCH(A20,'Risk Engine'!$E$4:$V$4,0) -> 15 | C20: {=INDEX('Country Profile'!$E$6:$V$6,$B20)} -> Africa | D20: {=INDEX('Risk Engine'!$E$5:$V$5,$B20)} -> 58.853407 | E20: {=INDEX('Risk Engine'!$E$6:$V$6,$B20)} -> 6 | F20: {=INDEX('Risk Engine'!$E$8:$V$8,$B20)} -> Stressed | G20: {=INDEX('Risk Engine'!$E$11:$V$11,$B20)} -> B | H20: {=INDEX('Risk Engine'!$E$19:$V$19,$B20)} -> 0.09187444 | I20: {=INDEX('Risk Engine'!$E$14:$V$14,$B20)} -> 0.066666667 | J20: {=INDEX('Risk Engine'!$E$29:$V$29,$B20)} -> 0.18556769 | K20: =IFERROR(__xludf.DUMMYFUNCTION("IFERROR(TEXTJOIN("", "",TRUE,SORTN(FILTER(Signals!$B$5:$B$22,INDEX(Signals!$E$5:$V$22,0,$B20)>=Assumptions!$B$65),3,0,FILTER(INDEX(Signals!$E$5:$V$22,0,$B20),INDEX(Signals!$E$5:$V$22,0,$B20)>=Assumptions!$B$65),FALSE)),""None above threshold"")"),"Debt payment wall, Commodity dependence, Inflation pressure") -> Debt payment wall, Commodity dependence, Inflation pressure | L20: {=COUNT(INDEX('Trade Activation'!$E$5:$V$26,0,$B20))} -> 7 | M20: {=IF(L20=0,"None",INDEX(Playbook!$B$5:$B$26,MATCH(MAX(INDEX('Trade Activation'!$E$5:$V$26,0,$B20)),INDEX('Trade Activation'!$E$5:$V$26,0,$B20),0)))} -> CDS curve flattener into a payment wall | N20: {=MAX(INDEX('Trade Activation'!$E$5:$V$26,0,$B20))} -> 100 | O20: {=Assumptions!$B$68*N20/100*INDEX(Assumptions!$E$52:$E$54,MATCH(F20,Assumptions!$A$52:$A$54,0))} -> 7.5 | P20: =IFERROR(__xludf.DUMMYFUNCTION("IF(L20=0,"""",TEXTJOIN("", "",TRUE,FILTER(Playbook!$A$5:$A$26,INDEX('Trade Activation'!$E$5:$V$26,0,$B20)<>"""")))"),"T01, T02, T06, T11, T12, T13, T16") -> T01, T02, T06, T11, T12, T13, T16
A21: Senegal | B21: =MATCH(A21,'Risk Engine'!$E$4:$V$4,0) -> 16 | C21: {=INDEX('Country Profile'!$E$6:$V$6,$B21)} -> Africa | D21: {=INDEX('Risk Engine'!$E$5:$V$5,$B21)} -> 56.4525 | E21: {=INDEX('Risk Engine'!$E$6:$V$6,$B21)} -> 6 | F21: {=INDEX('Risk Engine'!$E$8:$V$8,$B21)} -> Crisis | G21: {=INDEX('Risk Engine'!$E$11:$V$11,$B21)} -> CCC+ | H21: {=INDEX('Risk Engine'!$E$19:$V$19,$B21)} -> 0.35301985 | I21: {=INDEX('Risk Engine'!$E$14:$V$14,$B21)} -> 0.2 | J21: {=INDEX('Risk Engine'!$E$29:$V$29,$B21)} -> 0.42619828 | K21: =IFERROR(__xludf.DUMMYFUNCTION("IFERROR(TEXTJOIN("", "",TRUE,SORTN(FILTER(Signals!$B$5:$B$22,INDEX(Signals!$E$5:$V$22,0,$B21)>=Assumptions!$B$65),3,0,FILTER(INDEX(Signals!$E$5:$V$22,0,$B21),INDEX(Signals!$E$5:$V$22,0,$B21)>=Assumptions!$B$65),FALSE)),""None above threshold"")"),"Distress and restructuring, Official backstop stress, Market complacency") -> Distress and restructuring, Official backstop stress, Market complacency | L21: {=COUNT(INDEX('Trade Activation'!$E$5:$V$26,0,$B21))} -> 4 | M21: {=IF(L21=0,"None",INDEX(Playbook!$B$5:$B$26,MATCH(MAX(INDEX('Trade Activation'!$E$5:$V$26,0,$B21)),INDEX('Trade Activation'!$E$5:$V$26,0,$B21),0)))} -> Distressed recovery trade | N21: {=MAX(INDEX('Trade Activation'!$E$5:$V$26,0,$B21))} -> 100 | O21: {=Assumptions!$B$68*N21/100*INDEX(Assumptions!$E$52:$E$54,MATCH(F21,Assumptions!$A$52:$A$54,0))} -> 5 | P21: =IFERROR(__xludf.DUMMYFUNCTION("IF(L21=0,"""",TEXTJOIN("", "",TRUE,FILTER(Playbook!$A$5:$A$26,INDEX('Trade Activation'!$E$5:$V$26,0,$B21)<>"""")))"),"T03, T11, T18, T22") -> T03, T11, T18, T22
A22: Zambia | B22: =MATCH(A22,'Risk Engine'!$E$4:$V$4,0) -> 17 | C22: {=INDEX('Country Profile'!$E$6:$V$6,$B22)} -> Africa | D22: {=INDEX('Risk Engine'!$E$5:$V$5,$B22)} -> 52.46386 | E22: {=INDEX('Risk Engine'!$E$6:$V$6,$B22)} -> 6 | F22: {=INDEX('Risk Engine'!$E$8:$V$8,$B22)} -> Stressed | G22: {=INDEX('Risk Engine'!$E$11:$V$11,$B22)} -> CCC+ | H22: {=INDEX('Risk Engine'!$E$19:$V$19,$B22)} -> 0.15104901 | I22: {=INDEX('Risk Engine'!$E$14:$V$14,$B22)} -> 0.075 | J22: {=INDEX('Risk Engine'!$E$29:$V$29,$B22)} -> 0.20388021 | K22: =IFERROR(__xludf.DUMMYFUNCTION("IFERROR(TEXTJOIN("", "",TRUE,SORTN(FILTER(Signals!$B$5:$B$22,INDEX(Signals!$E$5:$V$22,0,$B22)>=Assumptions!$B$65),3,0,FILTER(INDEX(Signals!$E$5:$V$22,0,$B22),INDEX(Signals!$E$5:$V$22,0,$B22)>=Assumptions!$B$65),FALSE)),""None above threshold"")"),"Market complacency, Distress and restructuring, Commodity dependence") -> Market complacency, Distress and restructuring, Commodity dependence | L22: {=COUNT(INDEX('Trade Activation'!$E$5:$V$26,0,$B22))} -> 4 | M22: {=IF(L22=0,"None",INDEX(Playbook!$B$5:$B$26,MATCH(MAX(INDEX('Trade Activation'!$E$5:$V$26,0,$B22)),INDEX('Trade Activation'!$E$5:$V$26,0,$B22),0)))} -> Distressed recovery trade | N22: {=MAX(INDEX('Trade Activation'!$E$5:$V$26,0,$B22))} -> 100 | O22: {=Assumptions!$B$68*N22/100*INDEX(Assumptions!$E$52:$E$54,MATCH(F22,Assumptions!$A$52:$A$54,0))} -> 7.5 | P22: =IFERROR(__xludf.DUMMYFUNCTION("IF(L22=0,"""",TEXTJOIN("", "",TRUE,FILTER(Playbook!$A$5:$A$26,INDEX('Trade Activation'!$E$5:$V$26,0,$B22)<>"""")))"),"T06, T11, T13, T18") -> T06, T11, T13, T18
A23: Zimbabwe | B23: =MATCH(A23,'Risk Engine'!$E$4:$V$4,0) -> 18 | C23: {=INDEX('Country Profile'!$E$6:$V$6,$B23)} -> Africa | D23: {=INDEX('Risk Engine'!$E$5:$V$5,$B23)} -> 74.964737 | E23: {=INDEX('Risk Engine'!$E$6:$V$6,$B23)} -> 8 | F23: {=INDEX('Risk Engine'!$E$8:$V$8,$B23)} -> Crisis | G23: {=INDEX('Risk Engine'!$E$11:$V$11,$B23)} -> SD | H23: {=INDEX('Risk Engine'!$E$19:$V$19,$B23)} -> 0.99 | I23: {=INDEX('Risk Engine'!$E$14:$V$14,$B23)} -> 0.5 | J23: {=INDEX('Risk Engine'!$E$29:$V$29,$B23)} -> 0.9931702 | K23: =IFERROR(__xludf.DUMMYFUNCTION("IFERROR(TEXTJOIN("", "",TRUE,SORTN(FILTER(Signals!$B$5:$B$22,INDEX(Signals!$E$5:$V$22,0,$B23)>=Assumptions!$B$65),3,0,FILTER(INDEX(Signals!$E$5:$V$22,0,$B23),INDEX(Signals!$E$5:$V$22,0,$B23)>=Assumptions!$B$65),FALSE)),""None above threshold"")"),"Debt payment wall, Distress and restructuring, Market complacency") -> Debt payment wall, Distress and restructuring, Market complacency | L23: {=COUNT(INDEX('Trade Activation'!$E$5:$V$26,0,$B23))} -> 3 | M23: {=IF(L23=0,"None",INDEX(Playbook!$B$5:$B$26,MATCH(MAX(INDEX('Trade Activation'!$E$5:$V$26,0,$B23)),INDEX('Trade Activation'!$E$5:$V$26,0,$B23),0)))} -> Political risk insurance and concession underweight | N23: {=MAX(INDEX('Trade Activation'!$E$5:$V$26,0,$B23))} -> 90 | O23: {=Assumptions!$B$68*N23/100*INDEX(Assumptions!$E$52:$E$54,MATCH(F23,Assumptions!$A$52:$A$54,0))} -> 4.5 | P23: =IFERROR(__xludf.DUMMYFUNCTION("IF(L23=0,"""",TEXTJOIN("", "",TRUE,FILTER(Playbook!$A$5:$A$26,INDEX('Trade Activation'!$E$5:$V$26,0,$B23)<>"""")))"),"T11, T14, T15") -> T11, T14, T15

Sheet Assumptions
A1: Assumptions
A2: Blue cells are inputs. Values marked 'starting value' are first guesses to be fitted in the backtest.
A3: Scorecard aggregation | B3: Value | C3: Unit | D3: Source
A4: Worst-indicator blend weight | B4: 0.2 | C4: share | D4: Methodology fix 1 (base rule is 0.3)
A5: Minimum indicator weight for the worst-indicator term | B5: 0.1 | C5: weight in pillar | D5: Methodology fix 1 (base rule is 0)
A6: Maximum analyst adjustment | B6: 10 | C6: points | D6: Methodology rulebook
A7: Trigger add-on cap, pillars 3 and 4 | B7: 15 | C7: points | D7: Methodology rulebook
A8: Trigger add-on cap, pillar 7 | B8: 10 | C8: points | D8: Methodology rulebook
A9: Small-state test: population below | B9: 1.5 | C9: millions | D9: Methodology rulebook
A10: Small-state test: 1-in-100-year loss at or above | B10: 25 | C10: % of GDP | D10: Methodology rulebook
A11: Small-state climate pillar weight | B11: 0.15 | C11: weight | D11: Methodology rulebook
A13: Pillar | B13: Name | C13: Standard weight | D13: Small-state weight
A14: 1 | B14: Fiscal and debt | C14: 0.25 | D14: =IF(A14=7,$B$11,C14*(1-$B$11)/(1-$C$20)) -> 0.22368421
A15: 2 | B15: External | C15: 0.2 | D15: =IF(A15=7,$B$11,C15*(1-$B$11)/(1-$C$20)) -> 0.17894737
A16: 3 | B16: Institutions and governance | C16: 0.15 | D16: =IF(A16=7,$B$11,C16*(1-$B$11)/(1-$C$20)) -> 0.13421053
A17: 4 | B17: Political and policy | C17: 0.15 | D17: =IF(A17=7,$B$11,C17*(1-$B$11)/(1-$C$20)) -> 0.13421053
A18: 5 | B18: Macro and financial | C18: 0.1 | D18: =IF(A18=7,$B$11,C18*(1-$B$11)/(1-$C$20)) -> 0.089473684
A19: 6 | B19: Security and social | C19: 0.1 | D19: =IF(A19=7,$B$11,C19*(1-$B$11)/(1-$C$20)) -> 0.089473684
A20: 7 | B20: Climate and disaster | C20: 0.05 | D20: =IF(A20=7,$B$11,C20*(1-$B$11)/(1-$C$20)) -> 0.15
A21: Total | C21: =SUM(C14:C20) -> 1 | D21: =SUM(D14:D20) -> 1
A23: Stress path | B23: Value | C23: Unit | D23: Source
A24: Stress depreciation, floating currency | B24: 20 | C24: % | D24: Starting value
A25: Stress depreciation, managed float | B25: 15 | C25: % | D25: Starting value
A26: Stress depreciation, peg or dollarized | B26: 0 | C26: % (peg break sits in the Monte Carlo, per methodology fix) | D26: Methodology fix
A27: Growth shock | B27: -2 | C27: pp | D27: Starting value
A28: Interest rate shock | B28: 2 | C28: pp | D28: Starting value
A29: Share of debt repricing within a year | B29: 0.25 | C29: share | D29: Starting value
A30: Primary balance loss per 1pp of growth shock | B30: 0.3 | C30: pp of GDP | D30: Starting value
A31: Commodity export price shock | B31: -30 | C31: % | D31: Methodology (pillar 2 stress path)
A32: Tourism receipts shock | B32: -25 | C32: % | D32: Methodology (pillar 2 stress path)
A33: Manufacturing and services export shock | B33: -10 | C33: % | D33: Starting value
A34: Inflation pass-through from depreciation | B34: 0.3 | C34: share | D34: Methodology (pillar 5 stress path)
A36: Probability layer | B36: Value | C36: Unit | D36: Source
A37: Scorecard centre (universe average composite) | B37: =AVERAGE('Pillar Scores'!E46:V46) -> 45.767337 | C37: points | D37: Calculated
A38: Scorecard weight w_s | B38: 0.04 | C38: log-odds per point | D38: Starting value; fit on history (layer 2)
A39: Market signal weight w_m | B39: 0.5 | C39: share of market vs rating log-odds gap | D39: Starting value
A40: Text stress weight w_t | B40: 0.25 | C40: log-odds per z | D40: Starting value
A41: Loss given default used to back out market-implied PD | B41: 0.6 | C41: share | D41: Starting value
A42: Distress threshold: rating-implied PD at or above | B42: 0.12 | C42: probability | D42: Starting value (CCC+ and below)
A43: Minimum market-implied PD for mispricing signals | B43: 0.02 | C43: probability | D43: Starting value: below this, spreads are mostly risk and liquidity premium
...

Sheet Rulebook
A1: Rulebook: indicator thresholds and weights
A2: Each indicator is scored 0 to 100 by straight-line interpolation between its five threshold points. Level indicators take values 0 to 4, so each level maps to 0, 25, 50, 75 or 100. Thresholds are the methodology's first draft, to be fitted on the backtest.
A4: ID | B4: Pillar | C4: Indicator | D4: Unit | E4: Weight in pillar | F4: Type | G4: Scores 0 at | H4: Scores 25 at | I4: Scores 50 at | J4: Scores 75 at | K4: Scores 100 at | L4: Direction | M4: Stress path | N4: Level guide | O4: Source | P4: API or dataset for hookup | Q4: Low side 0 | R4: Low side 25 | S4: Low side 50 | T4: Low side 75 | U4: Low side 100
A5: 1.1 | B5: 1 | C5: Debt service (interest plus principal) | D5: % of revenue | E5: 0.2 | F5: Numeric | G5: 10 | H5: 20 | I5: 30 | J5: 45 | K5: 60 | L5: =SIGN(K5-G5) -> 1 | M5: N | O5: IMF Article IV DSA, budget documents | P5: Manual: IMF Article IV DSA tables
A6: 1.2 | B6: 1 | C6: FX debt service due in next 24 months | D6: % of FX reserves | E6: 0.15 | F6: Numeric | G6: 10 | H6: 25 | I6: 50 | J6: 75 | K6: 100 | L6: =SIGN(K6-G6) -> 1 | M6: N | O6: World Bank IDS projected debt service, Eurobond schedules, IMF reserves | P6: World Bank IDS API (DT.TDS.DPPG.CD) + IMF IRFCL
A7: 1.3 | B7: 1 | C7: Gross government debt | D7: % of GDP | E7: 0.15 | F7: Numeric | G7: 30 | H7: 45 | I7: 60 | J7: 80 | K7: 100 | L7: =SIGN(K7-G7) -> 1 | M7: Y | O7: IMF WEO; Randori stress path | P7: IMF DataMapper GGXWDG_NGDP
A8: 1.4 | B8: 1 | C8: Gross financing need | D8: % of GDP | E8: 0.1 | F8: Numeric | G8: 5 | H8: 10 | I8: 15 | J8: 20 | K8: 25 | L8: =SIGN(K8-G8) -> 1 | M8: Y | O8: IMF Article IV DSA / Fiscal Monitor; Randori stress path | P8: Manual: IMF Fiscal Monitor GFN table
A9: 1.5 | B9: 1 | C9: Foreign-currency share of government debt | D9: % of debt | E9: 0.1 | F9: Numeric | G9: 20 | H9: 35 | I9: 50 | J9: 65 | K9: 80 | L9: =SIGN(K9-G9) -> 1 | M9: N | O9: Article IV DSA, World Bank IDS | P9: World Bank IDS API
A10: 1.6 | B10: 1 | C10: Primary balance gap (actual minus debt-stabilizing) | D10: pp of GDP | E10: 0.05 | F10: Numeric | G10: 0 | H10: -1 | I10: -2 | J10: -3.5 | K10: -5 | L10: =SIGN(K10-G10) -> -1 | M10: Y | O10: Computed from WEO growth, rates and debt | P10: IMF DataMapper GGXONLB_G01_GDP_PT, NGDP_RPCH
A11: 1.7 | B11: 1 | C11: Change in debt/GDP over five years | D11: pp of GDP | E11: 0.05 | F11: Numeric | G11: -5 | H11: 0 | I11: 5 | J11: 10 | K11: 15 | L11: =SIGN(K11-G11) -> 1 | M11: Y | O11: IMF WEO; Randori stress path | P11: IMF DataMapper GGXWDG_NGDP (t minus t-5)
A12: 1.8 | B12: 1 | C12: Default record: restructurings or defaults, past 20 years | D12: count | E12: 0.1 | F12: Numeric | G12: 0 | H12: 0.5 | I12: 1 | J12: 2 | K12: 3 | L12: =SIGN(K12-G12) -> 1 | M12: N | O12: BoC-BoE sovereign default database | P12: Bank of Canada CRAG database (annual file)
A13: 1.9 | B13: 1 | C13: Contingent liabilities and arrears | D13: level | E13: 0.1 | F13: Level 0-4 | G13: 0 | H13: 1 | I13: 2 | J13: 3 | K13: 4 | L13: =SIGN(K13-G13) -> 1 | M13: N | N13: 0 none known | 1 small, disclosed | 2 guarantees >10% GDP or minor arrears | 3 arrears building or large SOE losses | 4 arrears >5% GDP or bank/SOE bailout under way | O13: Article IV, budget documents | P13: Manual: analyst
A14: 2.1 | B14: 2 | C14: Net usable reserves | D14: % of IMF ARA metric | E14: 0.15 | F14: Numeric | G14: 150 | H14: 125 | I14: 100 | J14: 75 | K14: 50 | L14: =SIGN(K14-G14) -> -1 | M14: Y | O14: IMF reserves template, IMF ARA data, central bank | P14: IMF ARA dataset (annual) + IMF IRFCL
A15: 2.2 | B15: 2 | C15: External financing need (CA deficit + external debt due in 12m) | D15: % of net reserves | E15: 0.15 | F15: Numeric | G15: 50 | H15: 75 | I15: 100 | J15: 150 | K15: 200 | L15: =SIGN(K15-G15) -> 1 | M15: N | O15: IMF BoP, World Bank IDS, BIS | P15: IMF BOP API + World Bank IDS API
A16: 2.3 | B16: 2 | C16: Hot money (non-resident local debt + portfolio due in 1y) | D16: % of net reserves | E16: 0.1 | F16: Numeric | G16: 10 | H16: 25 | I16: 50 | J16: 75 | K16: 100 | L16: =SIGN(K16-G16) -> 1 | M16: N | O16: Central bank, IMF sovereign investor base (Arslanalp-Tsuda) | P16: IMF Sovereign Investor Base dataset
A17: 2.4 | B17: 2 | C17: Dollarized banks: FX deposits | D17: % of deposits | E17: 0.1 | F17: Numeric | G17: 10 | H17: 25 | I17: 40 | J17: 55 | K17: 70 | L17: =SIGN(K17-G17) -> 1 | M17: N | O17: IMF Financial Soundness Indicators, central bank | P17: IMF FSI API
A18: 2.5 | B18: 2 | C18: Exchange regime and convertibility | D18: level | E18: 0.1 | F18: Level 0-4 | G18: 0 | H18: 1 | I18: 2 | J18: 3 | K18: 4 | L18: =SIGN(K18-G18) -> 1 | M18: N | N18: 0 free float, no controls | 1 managed float | 2 peg/dollarized with ample reserves, or parallel premium <10% | 3 peg below adequacy, multiple rates, or premium 10-50% | 4 premium >50%, FX rationing or active capital controls | O18: IMF AREAER, central bank, market reports | P18: Manual: IMF AREAER annual
A19: 2.6 | B19: 2 | C19: Official backstop: support available vs reliance | D19: level | E19: 0.1 | F19: Level 0-4 | G19: 0 | H19: 1 | I19: 2 | J19: 3 | K19: 4 | L19: =SIGN(K19-G19) -> 1 | M19: N | N19: 0 large precautionary line or major swap line unused | 1 IMF program on track or swaps undrawn | 2 no program, ordinary access | 3 program off track or drawn swaps/rolled deposits >25% reserves | 4 program suspended and drawn swaps/deposits >50% reserves | O19: IMF country pages, central bank, press | P19: Manual: IMF lending arrangements (MONA)
A20: 2.7 | B20: 2 | C20: Access to the dollar banking system | D20: level | E20: 0.05 | F20: Level 0-4 | G20: 0 | H20: 1 | I20: 2 | J20: 3 | K20: 4 | L20: =SIGN(K20-G20) -> 1 | M20: N | N20: 0 no issues | 1 some loss of correspondents | 2 FATF grey list | 3 grey list plus loss of major USD correspondents, or targeted sanctions | 4 FATF black list or sanctions blocking USD clearing | O20: FATF lists (Feb/Jun/Oct), World Bank/IMF correspondent banking reports | P20: Manual: FATF plenary lists
A21: 2.8 | B21: 2 | C21: Current account balance | D21: % of GDP | E21: 0.05 | F21: Numeric | G21: 0 | H21: -2 | I21: -4 | J21: -6 | K21: -8 | L21: =SIGN(K21-G21) -> -1 | M21: Y | O21: IMF WEO; Randori stress path | P21: IMF DataMapper BCA_NGDPD
A22: 2.9 | B22: 2 | C22: Short-term external debt | D22: % of net reserves | E22: 0.05 | F22: Numeric | G22: 10 | H22: 25 | I22: 50 | J22: 75 | K22: 100 | L22: =SIGN(K22-G22) -> 1 | M22: N | O22: World Bank IDS, BIS | P22: World Bank IDS API (DT.DOD.DSTC.IR.ZS)
A23: 2.10 | B23: 2 | C23: External debt | D23: % of exports of goods and services | E23: 0.05 | F23: Numeric | G23: 100 | H23: 150 | I23: 200 | J23: 250 | K23: 300 | L23: =SIGN(K23-G23) -> 1 | M23: N | O23: World Bank IDS | P23: World Bank IDS API (DT.DOD.DECT.EX.ZS)
A24: 2.11 | B24: 2 | C24: Export concentration: largest commodity or sector | D24: % of exports | E24: 0.05 | F24: Numeric | G24: 20 | H24: 35 | I24: 50 | J24: 65 | K24: 80 | L24: =SIGN(K24-G24) -> 1 | M24: N | O24: UN Comtrade, IMF BoP | P24: UN Comtrade API
A25: 2.12 | B25: 2 | C25: Real exchange rate vs 10-year average | D25: % above average | E25: 0.05 | F25: Numeric | G25: 0 | H25: 5 | I25: 10 | J25: 18 | K25: 25 | L25: =SIGN(K25-G25) -> 1 | M25: N | O25: BIS or IMF REER | P25: BIS REER API (broad)
A26: 3.1 | B26: 3 | C26: Record on investor treatment, past 20 years | D26: level | E26: 0.15 | F26: Level 0-4 | G26: 0 | H26: 1 | I26: 2 | J26: 3 | K26: 4 | L26: =SIGN(K26-G26) -> 1 | M26: N | N26: 0 none | 1 one case, negotiated and compensated | 2 one contested case or sector-wide renegotiation | 3 several cases or one without fair compensation | 4 nationalization program under way | O26: UNCTAD investment dispute database, Randori notes, press | P26: UNCTAD ISDS Navigator (manual)
A27: 3.2 | B27: 3 | C27: Arbitration award compliance | D27: level | E27: 0.15 | F27: Level 0-4 | G27: 0 | H27: 1 | I27: 2 | J27: 3 | K27: 4 | L27: =SIGN(K27-G27) -> 1 | M27: N | N27: 0 no awards or paid promptly | 1 paid within two years | 2 paid only after enforcement, or partly | 3 unpaid for over two years | 4 open refusal, asset seizures, or ICSID exit | O27: ICSID and UNCTAD case records, court filings | P27: ICSID case database (manual)
A28: 3.3 | B28: 3 | C28: Treaty protection | D28: level | E28: 0.1 | F28: Level 0-4 | G28: 0 | H28: 1 | I28: 2 | J28: 3 | K28: 4 | L28: =SIGN(K28-G28) -> 1 | M28: N | N28: 0 ICSID member, BITs in force with major investors | 1 ICSID member, few treaties | 2 not ICSID member, thin cover, or treaties under review | 3 treaties ended or consent withdrawn in past 10 years | 4 left ICSID or ended all BITs | O28: UNCTAD IIA Navigator, ICSID member list | P28: UNCTAD IIA Navigator (manual)
A29: 3.4 | B29: 3 | C29: Direction of change: 3-year change in WGI composite | D29: percentile points | E29: 0.1 | F29: Numeric | G29: 5 | H29: 0 | I29: -3 | J29: -6 | K29: -10 | L29: =SIGN(K29-G29) -> -1 | M29: N | O29: World Bank WGI | P29: World Bank WGI API (RL/CC/RQ .PER.RNK)
A30: 3.5 | B30: 3 | C30: WGI composite (rule of law, corruption, regulatory quality) | D30: percentile | E30: 0.1 | F30: Numeric | G30: 80 | H30: 60 | I30: 40 | J30: 25 | K30: 10 | L30: =SIGN(K30-G30) -> -1 | M30: N | O30: World Bank WGI | P30: World Bank WGI API (RL/CC/RQ .PER.RNK)
A31: 3.6 | B31: 3 | C31: Courts and legislature constrain the executive (V-Dem) | D31: index 0-1 | E31: 0.1 | F31: Numeric | G31: 0.85 | H31: 0.7 | I31: 0.5 | J31: 0.3 | K31: 0.15 | L31: =SIGN(K31-G31) -> -1 | M31: N | O31: V-Dem | P31: V-Dem dataset (v2x_jucon, v2xlg_legcon)
A32: 3.7 | B32: 3 | C32: Civil justice and contract enforcement (WJP) | D32: index 0-1 | E32: 0.1 | F32: Numeric | G32: 0.7 | H32: 0.6 | I32: 0.5 | J32: 0.4 | K32: 0.3 | L32: =SIGN(K32-G32) -> -1 | M32: N | O32: World Justice Project Rule of Law Index | P32: WJP Rule of Law Index (factor 7)
A33: 3.8 | B33: 3 | C33: Budget and data credibility | D33: level | E33: 0.1 | F33: Level 0-4 | G33: 0 | H33: 1 | I33: 2 | J33: 3 | K33: 4 | L33: =SIGN(K33-G33) -> 1 | M33: N | N33: 0 meets SDDS, no misreporting | 1 SDDS with gaps or e-GDDS met | 2 e-GDDS with gaps or weak open budget | 3 misreporting within 10 years or large unexplained revisions | 4 data suppressed, falsification, or hidden debt found | O33: IMF data standards, Open Budget Survey, PEFA, Article IV | P33: Manual: IMF DSBB
A34: 3.9 | B34: 3 | C34: State's growing role in strategic sectors | D34: level | E34: 0.05 | F34: Level 0-4 | G34: 0 | H34: 1 | I34: 2 | J34: 3 | K34: 4 | L34: =SIGN(K34-G34) -> 1 | M34: N | N34: 0 privatizing or stable private role | 1 state role stable | 2 larger stake in one sector, negotiated | 3 control in several sectors or local ownership mandates | 4 sector-wide nationalization policy | O34: Randori notes, press, OECD SOE data | P34: Manual: analyst
A35: 3.10 | B35: 3 | C35: Central bank independence in practice | D35: level | E35: 0.05 | F35: Level 0-4 | G35: 0 | H35: 1 | I35: 2 | J35: 3 | K35: 4 | L35: =SIGN(K35-G35) -> 1 | M35: N | N35: 0 independent, no monetary financing | 1 minor lapses | 2 governor replaced early or occasional monetary financing | 3 regular monetary financing | 4 financing the budget at scale or quasi-fiscal losses | O35: Article IV, central bank law and accounts, Garriga CBI index | P35: Manual: analyst
A36: 4.1 | B36: 4 | C36: Street pressure against promised adjustment | D36: level | E36: 0.15 | F36: Level 0-4 | G36: 0 | H36: 1 | I36: 2 | J36: 3 | K36: 4 | L36: =SIGN(K36-G36) -> 1 | M36: N | N36: 0 little adjustment or normal protests | 1 adjustment <1.5% GDP, protests slightly above normal | 2 adjustment >=1.5% GDP with protests above normal | 3 protests forced a reversal or turned deadly | 4 government fell or dropped IMF measures under street pressure | O36: Pillar 1 gap, ACLED/GDELT protest counts vs 5-year average | P36: ACLED API (protests) + analyst
A37: 4.2 | B37: 4 | C37: Military and elite cohesion | D37: level | E37: 0.1 | F37: Level 0-4 | G37: 0 | H37: 1 | I37: 2 | J37: 3 | K37: 4 | L37: =SIGN(K37-G37) -> 1 | M37: N | N37: 0 professional, paid, no purges | 1 minor grievances | 2 pay arrears or top commanders reshuffled | 3 purges, mutinies or rival armed units | 4 open split or mutiny | O37: Press, ACLED, Crisis Group, IISS | P37: Manual: analyst
A38: 4.3 | B38: 4 | C38: Regime type and factionalism | D38: level | E38: 0.1 | F38: Level 0-4 | G38: 0 | H38: 1 | I38: 2 | J38: 3 | K38: 4 | L38: =SIGN(K38-G38) -> 1 | M38: N | N38: 0 full democracy | 1 stable full autocracy | 2 partial autocracy | 3 partial democracy | 4 partial democracy with polarized, exclusionary factions | O38: V-Dem regime classification and polarization | P38: V-Dem dataset (v2x_regime, v2cacamps)
A39: 4.4 | B39: 4 | C39: Coup and irregular transfer of power | D39: level | E39: 0.1 | F39: Level 0-4 | G39: 0 | H39: 1 | I39: 2 | J39: 3 | K39: 4 | L39: =SIGN(K39-G39) -> 1 | M39: N | N39: 0 no attempt in 50 years | 1 last attempt >20 years ago | 2 attempt within 20 years or military active in politics | 3 attempt within 5 years or coup in a neighbor within 3 years | 4 successful coup within 5 years or military government | O39: Powell-Thyne coup data, Cline Center | P39: Powell-Thyne dataset (monthly file)
A40: 4.5 | B40: 4 | C40: Election timing and contestation | D40: level | E40: 0.1 | F40: Level 0-4 | G40: 0 | H40: 1 | I40: 2 | J40: 3 | K40: 4 | L40: =SIGN(K40-G40) -> 1 | M40: N | N40: 0 no national election within 24m, results accepted | 1 election within 24m, competitive | 2 election within 12m, polarized or strong anti-establishment challenger | 3 last result disputed or term-limit evasion | 4 election postponed/cancelled or results rejected with unrest | O40: IFES ElectionGuide, NELDA, V-Dem | P40: IFES ElectionGuide (manual)
A41: 4.6 | B41: 4 | C41: Policy predictability: abrupt changes by decree, past 5 years | D41: level | E41: 0.1 | F41: Level 0-4 | G41: 0 | H41: 1 | I41: 2 | J41: 3 | K41: 4 | L41: =SIGN(K41-G41) -> 1 | M41: N | N41: 0 none | 1 one, consulted and phased | 2 two or three, or one sudden and large | 3 frequent reversals | 4 rule by decree is routine | O41: Randori event log, Article IV, press | P41: Manual: analyst event log
...

Sheet Country Profile
A1: Country Profile: market data, flags and tradable instruments
A2: Blue values are inputs (seed estimates as of October 2026; replace with live feeds). Yes/No flags drive the override floors and the regime state. Instrument rows decide which trades in the Playbook can be expressed.
A4: ID | B4: Key | C4: Field | D4: Unit or source | E4: Vietnam | F4: Philippines | G4: China | H4: Malaysia | I4: Singapore | J4: Japan | K4: South Korea | L4: India | M4: Pakistan | N4: Belize | O4: Brazil | P4: Argentina | Q4: Colombia | R4: Venezuela | S4: Nigeria | T4: Senegal | U4: Zambia | V4: Zimbabwe
A5: P1 | B5: iso | C5: ISO code | E5: VNM | F5: PHL | G5: CHN | H5: MYS | I5: SGP | J5: JPN | K5: KOR | L5: IND | M5: PAK | N5: BLZ | O5: BRA | P5: ARG | Q5: COL | R5: VEN | S5: NGA | T5: SEN | U5: ZMB | V5: ZWE
A6: P2 | B6: region | C6: Region block (copula factor) | D6: Asia / LatAm / Africa | E6: Asia | F6: Asia | G6: Asia | H6: Asia | I6: Asia | J6: Asia | K6: Asia | L6: Asia | M6: Asia | N6: LatAm | O6: LatAm | P6: LatAm | Q6: LatAm | R6: LatAm | S6: Africa | T6: Africa | U6: Africa | V6: Africa
A7: P3 | B7: pop | C7: Population | D7: millions; World Bank SP.POP.TOTL | E7: 101 | F7: 115 | G7: 1408 | H7: 35.5 | I7: 6 | J7: 123.5 | K7: 51.7 | L7: 1460 | M7: 250 | N7: 0.42 | O7: 213 | P7: 46 | Q7: 53 | R7: 28 | S7: 235 | T7: 18.9 | U7: 21.5 | V7: 16.9
A8: P4 | B8: exports | C8: Exports of goods and services | D8: % of GDP; World Bank NE.EXP.GNFS.ZS | E8: 90 | F8: 27 | G8: 19 | H8: 68 | I8: 175 | J8: 22 | K8: 44 | L8: 21 | M8: 10 | N8: 50 | O8: 17 | P8: 14 | Q8: 15 | R8: 25 | S8: 15 | T8: 25 | U8: 40 | V8: 25
A9: P5 | B9: reserves | C9: Gross FX reserves | D9: % of GDP; IMF IRFCL | E9: 17 | F9: 22 | G9: 17 | H9: 27 | I9: 150 | J9: 28 | K9: 22 | L9: 17 | M9: 4 | N9: 14 | O9: 15 | P9: 6 | Q9: 15 | R9: 4 | S9: 8 | T9: 12 | U9: 13 | V9: 2
A10: P6 | B10: mainexp | C10: Main export | D10: UN Comtrade | E10: Electronics | F10: Electronics | G10: Manufactures | H10: Electrical and electronics | I10: Electronics and refined fuels | J10: Vehicles | K10: Semiconductors | L10: Refined fuels and IT services | M10: Textiles | N10: Tourism | O10: Soybeans, iron ore, oil | P10: Soy complex | Q10: Crude oil | R10: Crude oil | S10: Crude oil | T10: Gold and oil | U10: Copper | V10: Gold
A11: P7 | B11: exptype | C11: Main export type | D11: Commodity / Tourism / Manufacturing / Services | E11: Manufacturing | F11: Manufacturing | G11: Manufacturing | H11: Manufacturing | I11: Manufacturing | J11: Manufacturing | K11: Manufacturing | L11: Services | M11: Manufacturing | N11: Tourism | O11: Commodity | P11: Commodity | Q11: Commodity | R11: Commodity | S11: Commodity | T11: Commodity | U11: Commodity | V11: Commodity
A12: P8 | B12: commgap | C12: Main export price vs 10-year real average | D12: %; World Bank Pink Sheet | E12: 0 | F12: 0 | G12: 0 | H12: 0 | I12: 0 | J12: 0 | K12: 0 | L12: 0 | M12: 0 | N12: 0 | O12: -5 | P12: -10 | Q12: -15 | R12: -15 | S12: -15 | T12: 60 | U12: 35 | V12: 60
A13: P9 | B13: fxregime | C13: Exchange regime type | D13: Float / Managed / Peg / Dollarized | E13: Managed | F13: Float | G13: Managed | H13: Float | I13: Managed | J13: Float | K13: Float | L13: Managed | M13: Managed | N13: Peg | O13: Float | P13: Managed | Q13: Float | R13: Managed | S13: Float | T13: Peg | U13: Float | V13: Managed
A14: P10 | B14: rating | C14: S&P long-term FX rating | D14: S&P; estimate | E14: BB+ | F14: BBB+ | G14: A+ | H14: A- | I14: AAA | J14: A+ | K14: AA | L14: BBB | M14: B- | N14: B- | O14: BB | P14: B- | Q14: BB | R14: SD | S14: B | T14: CCC+ | U14: CCC+ | V14: SD
A15: P11 | B15: spread | C15: 5Y CDS or EMBI spread | D15: bps; Bloomberg/LSEG or JPM EMBI | E15: 100 | F15: 65 | G15: 60 | H15: 45 | I15: 15 | J15: 20 | K15: 25 | L15: 70 | M15: 450 | N15: 650 | O15: 160 | P15: 650 | Q15: 220 | R15: 6000 | S15: 400 | T15: 1200 | U15: 450 | V15: 3000
A16: P12 | B16: fx3m | C16: FX change vs USD, past 3 months | D16: % depreciation (+); FRED or central bank | E16: 0.5 | F16: 1 | G16: -0.5 | H16: -1 | I16: -0.5 | J16: 1 | K16: 0.5 | L16: 1.5 | M16: 0.5 | N16: 0 | O16: 0 | P16: 6 | Q16: -1 | R16: 35 | S16: 1 | T16: 0 | U16: -2 | V16: 8
A17: P13 | B17: res3m | C17: Reserves change, past 3 months | D17: %; IMF IRFCL | E17: -2 | F17: 1 | G17: 0 | H17: 1 | I17: 1 | J17: 0 | K17: 0 | L17: 1 | M17: 5 | N17: -3 | O17: 1 | P17: 6 | Q17: 0 | R17: -5 | S17: 2 | T17: -8 | U17: 3 | V17: -2
A18: P14 | B18: policy | C18: Policy rate | D18: %; BIS CBPOL | E18: 4.5 | F18: 4.5 | G18: 1.4 | H18: 2.75 | J18: 0.75 | K18: 2.5 | L18: 5.5 | M18: 11 | O18: 15 | Q18: 9.25 | R18: 59 | S18: 27 | T18: 3.25 | U18: 14.5 | V18: 35
A19: P15 | B19: election | C19: Next national election | D19: IFES ElectionGuide | E19: 2031 (National Assembly) | F19: May 2028 (general) | G19: None (NPC) | H19: By early 2028 (general) | I19: 2030 (general) | J19: 2028 (upper house) | K19: Apr 2028 (legislative) | L19: 2029 (general) | M19: 2029 (general) | N19: 2030 (general) | O19: Oct 2026 runoff | P19: Oct 2027 (presidential) | Q19: 2030 (presidential) | R19: Disputed 2024 result | S19: Feb 2027 (general) | T19: 2029 (presidential) | U19: 2031 (general) | V19: 2028 (general)
A20: P16 | B20: elmonths | C20: Months to next national election | D20: months | E20: 56 | F20: 19 | G20: 99 | H20: 16 | I20: 48 | J20: 21 | K20: 18 | L20: 31 | M20: 34 | N20: 45 | O20: 1 | P20: 12 | Q20: 43 | R20: 48 | S20: 4 | T20: 29 | U20: 58 | V20: 22
A21: P17 | B21: default | C21: In default or arrears to creditors | D21: Yes / No | E21: No | F21: No | G21: No | H21: No | I21: No | J21: No | K21: No | L21: No | M21: No | N21: No | O21: No | P21: No | Q21: No | R21: Yes | S21: No | T21: No | U21: No | V21: Yes
A22: P18 | B22: extarrears | C22: External arrears to commercial creditors | D22: Yes / No | E22: No | F22: No | G22: No | H22: No | I22: No | J22: No | K22: No | L22: No | M22: No | N22: No | O22: No | P22: No | Q22: No | R22: Yes | S22: No | T22: No | U22: No | V22: Yes
A23: P19 | B23: parallel | C23: Parallel market premium | D23: % | E23: 1 | F23: 0 | G23: 0 | H23: 0 | I23: 0 | J23: 0 | K23: 0 | L23: 0 | M23: 1 | N23: 2 | O23: 0 | P23: 3 | Q23: 0 | R23: 60 | S23: 2 | T23: 0 | U23: 0 | V23: 40
A24: P20 | B24: exprop | C24: Expropriation without compensation or asset seizure, past 3 years | D24: Yes / No | E24: No | F24: No | G24: No | H24: No | I24: No | J24: No | K24: No | L24: No | M24: No | N24: No | O24: No | P24: No | Q24: No | R24: Yes | S24: No | T24: No | U24: No | V24: No
A25: P21 | B25: coup | C25: Coup or unconstitutional change, past 12 months | D25: Yes / No | E25: No | F25: No | G25: No | H25: No | I25: No | J25: No | K25: No | L25: No | M25: No | N25: No | O25: No | P25: No | Q25: No | R25: No | S25: No | T25: No | U25: No | V25: No
A26: P22 | B26: nopay | C26: Stated intent not to pay debt | D26: Yes / No | E26: No | F26: No | G26: No | H26: No | I26: No | J26: No | K26: No | L26: No | M26: No | N26: No | O26: No | P26: No | Q26: No | R26: No | S26: No | T26: No | U26: No | V26: No
A27: P23 | B27: bankcrisis | C27: Banking crisis under way | D27: Yes / No | E27: No | F27: No | G27: No | H27: No | I27: No | J27: No | K27: No | L27: No | M27: No | N27: No | O27: No | P27: No | Q27: No | R27: No | S27: No | T27: No | U27: No | V27: No
A28: P24 | B28: emergency | C28: Nationwide state of emergency for armed violence | D28: Yes / No | E28: No | F28: No | G28: No | H28: No | I28: No | J28: No | K28: No | L28: No | M28: No | N28: No | O28: No | P28: No | Q28: No | R28: No | S28: No | T28: No | U28: No | V28: No
A29: P25 | B29: disaster | C29: Disaster loss of 10% of GDP or more, past 12 months | D29: Yes / No | E29: No | F29: No | G29: No | H29: No | I29: No | J29: No | K29: No | L29: No | M29: No | N29: No | O29: No | P29: No | Q29: No | R29: No | S29: No | T29: No | U29: No | V29: No
A30: P26 | B30: textz | C30: Text stress index | D30: z-score; layer 2 language-model index (not built yet) | E30: 0 | F30: 0 | G30: 0 | H30: 0 | I30: 0 | J30: 0 | K30: 0 | L30: 0 | M30: 0 | N30: 0 | O30: 0 | P30: 0 | Q30: 0 | R30: 0 | S30: 0 | T30: 0 | U30: 0 | V30: 0
A31: P27 | B31: prior | C31: Prior composite score (last run) | D31: points; paste last run's composite here
A32: P28 | B32: CDS | C32: Liquid sovereign CDS | D32: Yes / No | E32: No | F32: Yes | G32: Yes | H32: Yes | I32: No | J32: Yes | K32: Yes | L32: No | M32: Yes | N32: No | O32: Yes | P32: Yes | Q32: Yes | R32: No | S32: Yes | T32: No | U32: No | V32: No
